Workbook
Name COMBO1: [1]!COMBO[#Data]
Name ListaV: COMBO2!$A$1:$A$10
Name VIAJE: BASE_DATOS[[#All],[VIAJE]]

Sheet COMBO2
A1: VIAJE | B1: FECHA | C1: HORA | D1: TIEMPO Hrs | E1: ACTIVIDAD REALIZADA | F1: REFERENCIA | G1: DISTANCIA POR CARTA | H1: TIEMPO DE NAVEGACION | I1: VELOCIDAD | J1: BEAUFORT | K1: RPM | L1: MPAL | M1: AUX. | N1: CALDERA | O1: TOTAL | P1: FAENA | Q1: ROB | R1: MPAL2 | S1: AUX | T1: CALDERA | U1: PP | V1: GI | W1: TOTAL | X1: FAENA2 | Y1: ROB | Z1: CYLINDER MP | AA1: FAENA EN LTS | AB1: CYLINDER MP ROB EN LTS | AC1: CARTER MP. | AD1: FAENA EN LTS2 | AE1: CARTER MP. ROB EN LTS | AF1: MOT AUX | AG1: FAENA EN LTS | AH1: MOT AUX ROB EN LTS | AI1: HIDRAULICO | AJ1: FAENA EN LTS3 | AK1: HIDRAULICO ROB EN LTS
A2: V051-20 | B2: 43831 | C2: 0 | D2: 0 | E2: NAVEGANDO CON CARGA | F2: SUPE | I2: 0 | J2: S2 | K2: 95 | L2: 0 | M2: 0 | N2: 0 | O2: 0 | Q2: 370 | R2: 0 | S2: 0 | T2: 0 | U2: 0 | V2: 0 | W2: 0 | Y2: 94.34 | AB2: 100 | AE2: 100 | AH2: 100 | AK2: 100
A3: V052-20 | B3: 43840 | C3: 0.64583333 | D3: 0.5 | E3: MANIOBRA | F3: TCM CALLAO | I3: 0 | L3: 0.10416667 | M3: 0.052083333 | N3: 0.041666667 | O3: 0.19791667 | Q3: 274.80208 | R3: 0 | S3: 0 | T3: 0 | U3: 0 | V3: 0 | W3: 0 | Y3: 75.35 | AB3: 100 | AE3: 100 | AH3: 100 | AK3: 100
A4: V053-20 | B4: 43852 | C4: 0.875 | D4: 0.5 | E4: MANIOBRA | F4: CALLAO | I4: 0 | L4: 0.10416667 | M4: 0.052083333 | N4: 0.041666667 | O4: 0.19791667 | Q4: 165.82208 | R4: 0 | S4: 0 | T4: 0 | U4: 0 | V4: 0 | W4: 0 | Y4: 65.3 | AB4: 100 | AE4: 100 | AH4: 100 | AK4: 100
A5: V054-20 | B5: 43866 | C5: 0.52083333 | D5: 1 | E5: MANIOBRA | F5: TCM FONDEADO. | I5: 0 | L5: 0 | M5: 0 | N5: 0 | O5: 0 | Q5: 53 | R5: 0 | S5: 0 | T5: 0 | U5: 0 | V5: 0 | W5: 0 | X5: 0 | Y5: 56 | AB5: 100 | AE5: 100 | AH5: 100 | AK5: 100
A6: V055-20 | B6: 43878 | C6: 0.125 | D6: 0 | E6: MANIOBRA | F6: TCM CALLAO | I6: 0 | L6: 0.10416667 | M6: 0.052083333 | N6: 0.041666667 | O6: 0 | Q6: 752 | R6: 0 | S6: 0 | T6: 0 | U6: 0 | V6: 0 | W6: 0 | X6: 0 | Y6: 39 | AB6: 100 | AE6: 100 | AH6: 100 | AK6: 100
A7: V056-20 | B7: 43892 | C7: 0.825 | D7: 1 | E7: MANIOBRA | F7: TCM | I7: 0 | L7: 0.125 | M7: 0.0625 | N7: 0.05 | O7: 0 | Q7: 632 | R7: 0 | S7: 0 | T7: 0 | U7: 0 | V7: 0 | W7: 0 | X7: 0 | Y7: 27 | AB7: 100 | AE7: 100 | AH7: 100 | AK7: 100
A8: V057-20 | B8: 43919 | C8: 0.625 | D8: 1 | E8: MANIOBRA | F8: TCM | I8: 0 | L8: 0.041666667 | M8: 0.052083333 | N8: 0.041666667 | O8: 0 | Q8: 379 | R8: 0 | S8: 0 | T8: 0 | U8: 0 | V8: 0 | W8: 0 | X8: 0 | Y8: 82 | AB8: 100 | AE8: 100 | AH8: 100 | AK8: 100
A10: Total Viajes

Sheet BASE DATOS
G3: DATOS DE NAVEGACION | L3: CONSUMO VLSFO | R3: CONSUMO MGO | Z3: CONSUMO LUBRICANTES EN LTS
L4: MES ANTERIO | Q4: 370 | R4: MES ANTERIOR | Y4: 94.34 | AA4: MES ANT | AB4: 100 | AD4: MES ANT | AE4: 100 | AG4: MES ANT | AH4: 100 | AJ4: MES ANT | AK4: 100
A5: VIAJE | B5: FECHA | C5: HORA | D5: TIEMPO Hrs | E5: ACTIVIDAD REALIZADA | F5: REFERENCIA | G5: DISTANCIA POR CARTA | H5: TIEMPO DE NAVEGACION | I5: VELOCIDAD | J5: BEAUFORT | K5: RPM | L5: MPAL | M5: AUX. | N5: CALDERA | O5: TOTAL | P5: FAENA | Q5: ROB | R5: MPAL2 | S5: AUX | T5: CALDERA | U5: PP | V5: GI | W5: TOTAL | X5: FAENA2 | Y5: ROB | Z5: CYLINDER MP | AA5: FAENA EN LTS | AB5: CYLINDER MP ROB EN LTS | AC5: CARTER MP. | AD5: FAENA EN LTS2 | AE5: CARTER MP. ROB EN LTS | AF5: MOT AUX | AG5: FAENA EN LTS | AH5: MOT AUX ROB EN LTS | AI5: HIDRAULICO | AJ5: FAENA EN LTS3 | AK5: HIDRAULICO ROB EN LTS
A6: V051-19 | B6: 43821 | C6: 0.6875 | D6: 0.5 | E6: MANIOBRA | F6: FONDO CALLAO | I6: 0 | L6: 0.20833333 | M6: 0.052083333 | N6: 0.052083333 | O6: 0.3125 | Q6: 82.6875 | R6: 0 | S6: 0 | T6: 0 | U6: 0 | V6: 0 | W6: 0 | Y6: 94.34 | AB6: 100 | AE6: 100 | AH6: 100 | AK6: 100
A7: V051-19 | B7: 43822 | C7: 0.33333333 | D7: 15.5 | E7: FONDEADO | F7: FONDEADO | I7: 0 | L7: 0 | M7: 1.6145833 | N7: 1.6145833 | O7: 3.2291667 | Q7: 79.458333 | R7: 0 | S7: 0 | T7: 0 | U7: 0 | V7: 0 | W7: 0 | Y7: 94.34 | AB7: 100 | AE7: 100 | AH7: 100 | AK7: 100
A8: V051-19 | B8: 43822 | C8: 0.42916667 | D8: 2.3 | E8: FONDEADO | F8: ANCLA ARRIBA | I8: 0 | L8: 0 | M8: 0.23958333 | N8: 0.23958333 | O8: 0.47916667 | Q8: 78.979167 | R8: 0 | S8: 0 | T8: 0 | U8: 0 | V8: 0 | W8: 0 | Y8: 94.34 | AB8: 100 | AE8: 100 | AH8: 100 | AK8: 100
A9: V051-19 | B9: 43822 | C9: 0.49166667 | D9: 1.5 | E9: MANIOBRA | F9: INICIO MANIOBRA | I9: 0 | L9: 0 | M9: 0.15625 | N9: 0.15625 | O9: 0.3125 | Q9: 78.666667 | R9: 0 | S9: 0 | T9: 0 | U9: 0 | V9: 0 | W9: 0 | Y9: 94.34 | AB9: 100 | AE9: 100 | AH9: 100 | AK9: 100
A10: V051-19 | B10: 43822 | C10: 0.525 | D10: 0.8 | E10: MANIOBRA | F10: TCM | I10: 0 | L10: 0.33333333 | M10: 0.083333333 | N10: 0.083333333 | O10: 0.5 | Q10: 78.166667 | R10: 0 | S10: 0 | T10: 0 | U10: 0 | V10: 0 | W10: 0 | Y10: 94.34 | AB10: 100 | AE10: 100 | AH10: 100 | AK10: 100
A11: V051-19 | B11: 43823 | C11: 0.33333333 | D11: 19.4 | E11: OTRAS ACT. | F11: CARGANDO | I11: 0 | L11: 0 | M11: 2.0208333 | N11: 2.0208333 | O11: 4.0416667 | Q11: 74.125 | R11: 0 | S11: 0.1 | T11: 0 | U11: 0 | V11: 0 | W11: 0.1 | Y11: 94.24 | AB11: 100 | AE11: 100 | AH11: 100 | AK11: 100
A12: V051-19 | B12: 43824 | C12: 0.125 | D12: 19 | E12: CARGANDO | F12: TERMINO CARGA | I12: 0 | L12: 0 | M12: 1.9791667 | N12: 1.9791667 | O12: 3.9583333 | Q12: 70.166667 | R12: 0 | S12: 0 | T12: 0 | U12: 0 | V12: 0 | W12: 0 | Y12: 94.24 | AB12: 100 | AE12: 100 | AH12: 100 | AK12: 100
A13: V051-19 | B13: 43824 | C13: 0.28333333 | D13: 3.8 | E13: OTRAS ACT. | F13: INICIO MANIOBRA | I13: 0 | L13: 0 | M13: 0.39583333 | N13: 0.39583333 | O13: 0.79166667 | Q13: 69.375 | R13: 0 | S13: 0 | T13: 0 | U13: 0 | V13: 0 | W13: 0 | Y13: 94.24 | AB13: 100 | AE13: 100 | AH13: 100 | AK13: 100
A14: V051-19 | B14: 43824 | C14: 0.30416667 | D14: 0.5 | E14: MANIOBRA | F14: TCM | I14: 0 | L14: 0.20833333 | M14: 0.052083333 | N14: 0.052083333 | O14: 0.3125 | Q14: 69.0625 | R14: 0 | S14: 0 | T14: 0 | U14: 0 | V14: 0 | W14: 0 | Y14: 94.24 | AB14: 100 | AE14: 100 | AH14: 100 | AK14: 100
A15: V051-19 | B15: 43824 | C15: 0.33333333 | D15: 0.7 | E15: MANIOBRA | F15: ZARPE. IVM | I15: 0 | L15: 0.72916667 | M15: 0.072916667 | N15: 0.072916667 | O15: 0.875 | Q15: 68.1875 | R15: 0 | S15: 0 | T15: 0 | U15: 0 | V15: 0 | W15: 0 | Y15: 94.24 | AB15: 100 | AE15: 100 | AH15: 100 | AK15: 100
A16: V051-19 | B16: 43824 | C16: 0.77916667 | D16: 10.7 | E16: NAVEGANDO CON CARGA | F16: ARRIBO PISCO | I16: 0 | L16: 11.145833 | M16: 1.1145833 | N16: 1.1145833 | O16: 13.375 | Q16: 54.8125 | R16: 0 | S16: 0 | T16: 0 | U16: 0 | V16: 0 | W16: 0 | Y16: 94.24 | AB16: 100 | AE16: 100 | AH16: 100 | AK16: 100
A17: V051-19 | B17: 43824 | C17: 0.82083333 | D17: 1 | E17: MANIOBRA | F17: FONDO PISCO | I17: 0 | L17: 0.41666667 | M17: 0.10416667 | N17: 0.10416667 | O17: 0.625 | Q17: 54.1875 | R17: 0 | S17: 0.1 | T17: 0 | U17: 0 | V17: 0 | W17: 0.1 | Y17: 94.14 | AB17: 100 | AE17: 100 | AH17: 100 | AK17: 100
... A43: V051-19 | B43: 43830 | C43: 0.95 | D43: 8.1 | E43: OTRAS ACT. | F43: ANCLA ARRIBA | I43: 0 | L43: 0 | M43: 0 | N43: 0 | O43: 0 | Q43: 0.005 | R43: 0 | S43: 0.2 | T43: 0.1 | U43: 0 | V43: 0 | W43: 0.3 | Y43: 88.98 | AB43: 100 | AE43: 100 | AH43: 100 | AK43: 100
A44: V051-19 | B44: 43830 | C44: 0.97916667 | D44: 0.7 | E44: OTRAS ACT. | F44: ZARPE | I44: 0 | L44: 0 | M44: 0 | N44: 0 | O44: 0 | P44: 370 | Q44: 370.005 | R44: 0.29 | S44: 0.1 | T44: 0.1 | U44: 0 | V44: 0 | W44: 0.49 | Y44: 88.49 | AB44: 100 | AE44: 100 | AH44: 100 | AK44: 100
A45: V051-20 | B45: 43831 | C45: 0.3 | D45: 7.2 | E45: NAVEGANDO CON CARGA | F45: ARRIBO SUPE | G45: 91 | H45: 7.2 | I45: 12.638889 | J45: S2 | K45: 95 | L45: 0 | M45: 0 | N45: 0 | O45: 0 | Q45: 370 | R45: 7.5 | S45: 0.75 | T45: 0.06 | U45: 0 | V45: 0 | W45: 8.31 | Y45: 86.03 | AB45: 100 | AE45: 100 | AH45: 100 | AK45: 100
A46: V051-20 | B46: 43831 | C46: 0.33333333 | D46: 0.8 | E46: MANIOBRA | F46: SUPE | I46: 0 | L46: 0 | M46: 0 | N46: 0 | O46: 0 | Q46: 370 | R46: 0.33 | S46: 0.08 | T46: 0.07 | U46: 0 | V46: 0 | W46: 0.48 | X46: 0 | Y46: 85.55 | AB46: 100 | AE46: 100 | AH46: 100 | AK46: 100
A47: V051-20 | B47: 43831 | C47: 0.35 | D47: 0.4 | E47: MANIOBRA | F47: INICIO MANIOBRA SUPE | I47: 0 | L47: 0 | M47: 0.041666667 | N47: 0.033333333 | O47: 0.075 | Q47: 369.925 | R47: 0 | S47: 0 | T47: 0 | U47: 0 | V47: 0 | W47: 0 | Y47: 85.55 | AB47: 100 | AE47: 100 | AH47: 100 | AK47: 100
A48: V051-20 | B48: 43831 | C48: 0.3875 | D48: 0.9 | E48: MANIOBRA | F48: TCM SUPE | I48: 0 | L48: 0.375 | M48: 0.09375 | N48: 0.075 | O48: 0.54375 | Q48: 369.38125 | R48: 0 | S48: 0 | T48: 0 | U48: 0 | V48: 0 | W48: 0 | Y48: 85.55 | AB48: 100 | AE48: 100 | AH48: 100 | AK48: 100
A49: V051-20 | B49: 43831 | C49: 0.50416667 | D49: 2.8 | E49: OTRAS ACT. | F49: INICIO DESCARGA SUPE | I49: 0 | L49: 0 | M49: 0.29166667 | N49: 0.23333333 | O49: 0.525 | Q49: 368.85625 | R49: 0 | S49: 0 | T49: 0 | U49: 0 | V49: 0 | W49: 0 | Y49: 85.55 | AB49: 100 | AE49: 100 | AH49: 100 | AK49: 100
A50: V051-20 | B50: 43831 | C50: 0.95833333 | D50: 10.9 | E50: DESCARGANDO | F50: TERMINO DESARGA SUPE | I50: 0 | L50: 0 | M50: 1.1354167 | N50: 0.90833333 | O50: 2.04375 | Q50: 366.8125 | R50: 0 | S50: 0 | T50: 0 | U50: 0 | V50: 2.8 | W50: 2.8 | Y50: 82.75 | AB50: 100 | AE50: 100 | AH50: 100 | AK50: 100
A51: V051-20 | B51: 43832 | C51: 0.0875 | D51: 3.1 | E51: OTRAS ACT. | F51: INICIO MANIOBRA ZARPE SUPE | I51: 0 | L51: 0 | M51: 0.32291667 | N51: 0.25833333 | O51: 0.58125 | Q51: 366.23125 | R51: 0 | S51: 0 | T51: 0 | U51: 0 | V51: 0 | W51: 0 | Y51: 82.75 | AB51: 100 | AE51: 100 | AH51: 100 | AK51: 100
A52: V051-20 | B52: 43832 | C52: 0.1125 | D52: 0.6 | E52: MANIOBRA | F52: ZARPE SUPE | I52: 0 | L52: 0.25 | M52: 0.0625 | N52: 0.05 | O52: 0.3625 | Q52: 365.86875 | R52: 0 | S52: 0 | T52: 0 | U52: 0 | V52: 0 | W52: 0 | Y52: 82.75 | AB52: 100 | AE52: 100 | AH52: 100 | AK52: 100
A53: V051-20 | B53: 43832 | C53: 0.33333333 | D53: 5.3 | E53: NAVEGANDO CON CARGA | F53: NAVEGANDO A ETEN | I53: 0 | J53: S2 | K53: 95 | L53: 5.5208333 | M53: 0.55208333 | N53: 0.44166667 | O53: 6.5145833 | Q53: 359.35417 | R53: 0 | S53: 0 | T53: 0 | U53: 0 | V53: 0 | W53: 0 | Y53: 82.75 | AB53: 100 | AE53: 100 | AH53: 100 | AK53: 100
A54: V051-20 | B54: 43833 | C54: 0.095833333 | D54: 18.3 | E54: NAVEGANDO CON CARGA | F54: ARRIBO ETEN | G54: 266 | H54: 23.6 | I54: 11.271186 | J54: S 2 | K54: 95 | L54: 19.0625 | M54: 1.90625 | N54: 1.525 | O54: 22.49375 | Q54: 336.86042 | R54: 0 | S54: 0 | T54: 0 | U54: 0 | V54: 0 | W54: 0 | Y54: 82.75 | AB54: 100 | AE54: 100 | AH54: 100 | AK54: 100
A55: V051-20 | B55: 43833 | C55: 0.11666667 | D55: 0.5 | E55: MANIOBRA | F55: TCM FONDEADO ETEN | I55: 0 | L55: 0.20833333 | M55: 0.052083333 | N55: 0.041666667 | O55: 0.30208333 | Q55: 336.55833 | R55: 0 | S55: 0 | T55: 0 | U55: 0 | V55: 0 | W55: 0 | Y55: 82.75 | AB55: 100 | AE55: 100 | AH55: 100 | AK55: 100
A56: V051-20 | B56: 43833 | C56: 0.33333333 | D56: 5.2 | E56: FONDEADO | F56: ETEN | I56: 0 | L56: 0 | M56: 0.54166667 | N56: 0.43333333 | O56: 0.975 | Q56: 335.58333 | R56: 0 | S56: 0 | T56: 0 | U56: 0 | V56: 0 | W56: 0 | Y56: 82.75 | AB56: 100 | AE56: 100 | AH56: 100 | AK56: 100
A57: V051-20 | B57: 43834 | C57: 0.33333333 | D57: 24 | E57: FONDEADO | F57: ETEN | I57: 0 | L57: 0 | M57: 2.5 | N57: 2 | O57: 4.5 | Q57: 331.08333 | R57: 0 | S57: 0 | T57: 0 | U57: 0 | V57: 0 | W57: 0 | Y57: 82.75 | AB57: 100 | AE57: 100 | AH57: 100 | AK57: 100
A58: V051-20 | B58: 43835 | C58: 0.33333333 | D58: 24 | E58: FONDEADO | F58: ETEN | I58: 0 | L58: 0 | M58: 2.2 | N58: 2 | O58: 4.2 | Q58: 326.88333 | R58: 0 | S58: 0 | T58: 0 | U58: 0 | V58: 0 | W58: 0 | Y58: 82.75 | AB58: 100 | AE58: 100 | AH58: 100 | AK58: 100
A59: V051-20 | B59: 43836 | C59: 0.33333333 | D59: 24 | E59: FONDEADO | F59: ETEN | I59: 0 | L59: 0 | M59: 2.2 | N59: 2 | O59: 4.2 | Q59: 322.68333 | R59: 0 | S59: 0 | T59: 0 | U59: 0 | V59: 0 | W59: 0 | Y59: 82.75 | AB59: 100 | AE59: 100 | AH59: 100 | AK59: 100
A60: V051-20 | B60: 43836 | C60: 0.54166667 | D60: 5 | E60: FONDEADO | F60: ANCLA ARRIBA ETEN | I60: 0 | L60: 0 | M60: 0.45833333 | N60: 0.41666667 | O60: 0.875 | Q60: 321.80833 | R60: 0 | S60: 0 | T60: 0 | U60: 0 | V60: 0 | W60: 0 | Y60: 82.75 | AB60: 100 | AE60: 100 | AH60: 100 | AK60: 100
A61: V051-20 | B61: 43836 | C61: 0.59583333 | D61: 1.3 | E61: MANIOBRA | F61: TCM ETEN | I61: 0 | L61: 0.10833333 | M61: 0.11916667 | N61: 0.10833333 | O61: 0.33583333 | Q61: 321.4725 | R61: 0 | S61: 0 | T61: 0 | U61: 0 | V61: 0 | W61: 0 | Y61: 82.75 | AB61: 100 | AE61: 100 | AH61: 100 | AK61: 100
A62: V051-20 | B62: 43836 | C62: 0.72083333 | D62: 3 | E62: OTRAS ACT. | F62: INICIO DESCARGA ETEN | I62: 0 | L62: 0 | M62: 0.3125 | N62: 0.25 | O62: 0.5625 | Q62: 320.91 | R62: 0 | S62: 0 | T62: 0 | U62: 0 | V62: 0 | W62: 0 | Y62: 82.75 | AB62: 100 | AE62: 100 | AH62: 100 | AK62: 100
A63: V051-20 | B63: 43837 | C63: 0.33333333 | D63: 14.7 | E63: DESCARGANDO | F63: DESCARGANDO | I63: 0 | L63: 0 | M63: 1.53125 | N63: 1.225 | O63: 2.75625 | Q63: 318.15375 | R63: 0 | S63: 0 | T63: 0 | U63: 0 | V63: 2.3 | W63: 2.3 | Y63: 80.45 | AB63: 100 | AE63: 100 | AH63: 100 | AK63: 100
A64: V051-20 | B64: 43837 | C64: 0.88333333 | D64: 13.2 | E64: DESCARGANDO | F64: TERMINO DESCARGA ETEN | I64: 0 | L64: 0 | M64: 1.375 | N64: 1.1 | O64: 2.475 | Q64: 315.67875 | R64: 0 | S64: 0 | T64: 0 | U64: 0 | V64: 2.2 | W64: 2.2 | Y64: 78.25 | AB64: 100 | AE64: 100 | AH64: 100 | AK64: 100
A65: V051-20 | B65: 43838 | C65: 0.016666667 | D65: 3.2 | E65: OTRAS ACT. | F65: ANCLA ARRIBA ETEN | I65: 0 | L65: 0 | M65: 0.33333333 | N65: 0.26666667 | O65: 0.6 | Q65: 315.07875 | R65: 0 | S65: 0 | T65: 0 | U65: 0 | V65: 0 | W65: 0 | Y65: 78.25 | AB65: 100 | AE65: 100 | AH65: 100 | AK65: 100
A66: V051-20 | B66: 43838 | C66: 0.041666667 | D66: 0.6 | E66: MANIOBRA | F66: INICIO VIAJE SALAVERRY | I66: 0 | L66: 0.125 | M66: 0.0625 | N66: 0.05 | O66: 0.2375 | Q66: 314.84125 | R66: 0 | S66: 0 | T66: 0 | U66: 0 | V66: 0 | W66: 0 | Y66: 78.25 | AB66: 100 | AE66: 100 | AH66: 100 | AK66: 100
A67: V051-20 | B67: 43838 | C67: 0.33333333 | D67: 7 | E67: NAVEGANDO CON CARGA | F67: SALAVERRY | I67: 0 | J67: S3 | K67: 95 | L67: 6.4166667 | M67: 0.72916667 | N67: 0 | O67: 7.1458333 | Q67: 307.69542 | R67: 0 | S67: 0 | T67: 0 | U67: 0 | V67: 0 | W67: 0 | Y67: 78.25 | AB67: 100 | AE67: 100 | AH67: 100 | AK67: 100
...

Sheet GRAFICA 
AE12: =CONCATENATE("VELOCIDAD EN ",D53) -> VELOCIDAD EN NAVEGACION ECONOMICA
A15: VELOCIDAD
A22: CARGANDO
A23: DESCARGANDO | C23: ACTIVIDAD | D23: CARGANDO
A24: NAVEGANDO EN LASTRE | C24: VIAJE | D24: V051-20 | E24: V052-20 | F24: V053-20 | G24: V054-20 | H24: V055-20 | I24: V056-20 | J24: V057-20 | K24: VIAJE 8 | L24: VIAJE 9 | M24: VIAJE 10 | N24: VIAJE 11 | O24: VIAJE 12
A25: NAVEGANDO CON CARGA | C25: CONSUMO CONTRATO | D25: =IF($D$23='V051-19'!$R$82,'V051-19'!$U$82,VLOOKUP($D$23,'V051-19'!$C$81:$N$89,8,FALSE)) -> 4.5 | E25: =IF($D$23='V052-20'!$Q$62,'V052-20'!$T$62,VLOOKUP($D$23,'V052-20'!$C$61:$N$69,8,FALSE)) -> 4.5 | F25: =IF($D$23='V053-20'!$R$57,'V053-20'!$U$57,VLOOKUP($D$23,'V053-20'!$C$56:$N$64,8,FALSE)) -> 4.5 | G25: =IF($D$23='V054-20'!$R$54,'V054-20'!$U$54,VLOOKUP($D$23,'V054-20'!$C$53:$N$61,8,FALSE)) -> 4.5 | H25: =IF($D$23='V055-20'!$R$63,'V055-20'!$U$63,VLOOKUP($D$23,'V055-20'!$C$62:$N$70,8,FALSE)) -> 4.5 | I25: =IF($D$23='V056-20'!$R$82,'V056-20'!$U$82,VLOOKUP($D$23,'V056-20'!$C$81:$N$89,8,FALSE)) -> 4.5 | J25: =IF($D$23=#REF!,#REF!,VLOOKUP($D$23,#REF!,8,FALSE)) -> #REF! | K25: =IF($D$23=#REF!,#REF!,VLOOKUP($D$23,#REF!,8,FALSE)) -> #REF! | L25: =IF($D$23=#REF!,#REF!,VLOOKUP($D$23,#REF!,8,FALSE)) -> #REF! | M25: =IF($D$23=#REF!,#REF!,VLOOKUP($D$23,#REF!,8,FALSE)) -> #REF! | N25: =IF($D$23=#REF!,#REF!,VLOOKUP($D$23,#REF!,8,FALSE)) -> #REF! | O25: =IF($D$23=#REF!,#REF!,VLOOKUP($D$23,#REF!,8,FALSE)) -> #REF!
A26: FONDEADO | C26: CONSUMO VIAJE | D26: =IF($D$23='V051-19'!$R$82,'V051-19'!$T$82,VLOOKUP($D$23,'V051-19'!C81:N89,7,FALSE)) -> 7.0501792 | E26: =IF($D$23='V052-20'!$Q$62,'V052-20'!$S$62,VLOOKUP($D$23,'V052-20'!$C$61:$N$69,7,FALSE)) -> 4.5 | F26: =IF($D$23='V053-20'!$R$57,'V053-20'!$T$57,VLOOKUP($D$23,'V053-20'!$C$56:$N$64,8,FALSE)) -> 4.5 | G26: =IF($D$23='V054-20'!$R$54,'V054-20'!$T$54,VLOOKUP($D$23,'V054-20'!C53:N61,7,FALSE)) -> 4 | H26: =IF($D$23='V055-20'!$R$63,'V055-20'!$T$63,VLOOKUP($D$23,'V055-20'!$C$62:$N$70,7,FALSE)) -> 4.5 | I26: =IF($D$23='V056-20'!$R$82,'V056-20'!$T$82,VLOOKUP($D$23,'V056-20'!$C$81:$N$89,7,FALSE)) -> 4.5 | J26: =IF($D$23=#REF!,#REF!,VLOOKUP($D$23,#REF!,7,FALSE)) -> #REF! | K26: =IF($D$23=#REF!,#REF!,VLOOKUP($D$23,#REF!,7,FALSE)) -> #REF! | L26: =IF($D$23=#REF!,#REF!,VLOOKUP($D$23,#REF!,7,FALSE)) -> #REF! | M26: =IF($D$23=#REF!,#REF!,VLOOKUP($D$23,#REF!,7,FALSE)) -> #REF! | N26: =IF($D$23=#REF!,#REF!,VLOOKUP($D$23,#REF!,7,FALSE)) -> #REF! | O26: =IF($D$23=#REF!,#REF!,VLOOKUP($D$23,#REF!,7,FALSE)) -> #REF!
A27: MANIOBRA
A28: OTRAS ACT.
A29: GAS INERT
A32: NAVEGANDO EN LASTRE
A33: NAVEGANDO CON CARGA
C53: ACTIVIDAD | D53: NAVEGACION ECONOMICA
C54: VIAJE | D54: V051-20 | E54: V052-20 | F54: V053-20 | G54: V054-20 | H54: V055-20 | I54: V056-20 | J54: V057-20 | K54: VIAJE 8 | L54: VIAJE 9 | M54: VIAJE 10 | N54: VIAJE 11 | O54: VIAJE 12
C55: VELOCIDAD CONTRATO | D55: =VLOOKUP($D$53,'V051-19'!$C$81:$N$89,5,FALSE) -> 12 | E55: =VLOOKUP($D$53,'V052-20'!$C$61:$N$69,5,FALSE) -> 12 | F55: =VLOOKUP($D$53,'V053-20'!$C$56:$N$64,5,FALSE) -> 12 | G55: =VLOOKUP($D$53,'V054-20'!$C$53:$N$61,5,FALSE) -> 12 | H55: =VLOOKUP($D$53,'V055-20'!$C$62:$N$70,5,FALSE) -> 12 | I55: =VLOOKUP($D$53,'V056-20'!$C$81:$N$89,5,FALSE) -> 12 | J55: =VLOOKUP($D$53,#REF!,5,FALSE) -> #REF! | K55: =VLOOKUP($D$53,#REF!,5,FALSE) -> #REF! | L55: =VLOOKUP($D$53,#REF!,5,FALSE) -> #REF! | M55: =VLOOKUP($D$53,#REF!,5,FALSE) -> #REF! | N55: =VLOOKUP($D$53,#REF!,5,FALSE) -> #REF! | O55: =VLOOKUP($D$53,#REF!,5,FALSE) -> #REF!
C56: VELOCIDAD VIAJE | D56: =VLOOKUP($D$53,'V051-19'!$C$81:$N$89,4,FALSE) -> 0 | E56: =VLOOKUP($D$53,'V052-20'!$C$61:$N$69,4,FALSE) -> 0 | F56: =VLOOKUP($D$53,'V053-20'!$C$56:$N$64,4,FALSE) -> 0 | G56: =VLOOKUP($D$53,'V054-20'!C53:N61,4,FALSE) -> 0 | H56: =VLOOKUP($D$53,'V055-20'!$C$62:$N$70,4,FALSE) -> 0 | I56: =VLOOKUP($D$53,'V056-20'!$C$81:$N$89,4,FALSE) -> 0 | J56: =VLOOKUP($D$53,#REF!,4,FALSE) -> #REF! | K56: =VLOOKUP($D$53,#REF!,4,FALSE) -> #REF! | L56: =VLOOKUP($D$53,#REF!,4,FALSE) -> #REF! | M56: =VLOOKUP($D$53,#REF!,4,FALSE) -> #REF! | N56: =VLOOKUP($D$53,#REF!,4,FALSE) -> #REF! | O56: =VLOOKUP($D$53,#REF!,4,FALSE) -> #REF!

Sheet V051-19
G3: DATOS DE NAVEGACION | L3: CONSUMO VLSFO | R3: CONSUMO MGO | Z3: CONSUMO LUBRICANTES EN LTS
A4: INICIO | B4: 43821 | C4: 0.66666667 | L4: VIAJE ANTERIO | Q4: 83 | R4: VIAJE ANTERIOR | Y4: 20.9 | AA4: VIAJE ANT | AB4: 100 | AD4: VIAJE ANT | AE4: 100 | AG4: VIAJE ANT | AH4: 100 | AJ4: VIAJE ANT | AK4: 100
A5: VIAJE | B5: FECHA | C5: HORA | D5: TIEMPO Hrs | E5: ACTIVIDAD REALIZADA | F5: REFERENCIA | G5: DISTANCIA POR CARTA | H5: TIEMPO DE NAVEGACION | I5: VELOCIDAD | J5: BEAUFORT | K5: RPM | L5: MPAL | M5: AUX. | N5: CALDERA | O5: TOTAL | P5: FAENA | Q5: ROB | R5: MPAL2 | S5: AUX | T5: CALDERA | U5: PP | V5: GI | W5: TOTAL | X5: FAENA2 | Y5: ROB | Z5: CYLINDER MP | AA5: FAENA EN LTS | AB5: CYLINDER MP ROB EN LTS | AC5: CARTER MP. | AD5: FAENA EN LTS2 | AE5: CARTER MP. ROB EN LTS | AF5: MOT AUX | AG5: FAENA EN LTS | AH5: MOT AUX ROB EN LTS | AI5: HIDRAULICO | AJ5: FAENA EN LTS3 | AK5: HIDRAULICO ROB EN LTS
A6: V051-19 | B6: 43821 | C6: 0.6875 | D6: =IF(V051_20[[#This Row],[FECHA]]-B4=1,((V051_20[[#This Row],[HORA]]-C4)*24)+24,(V051_20[[#This Row],[HORA]]-C4)*24) -> 0.5 | E6: MANIOBRA | F6: FONDO CALLAO | I6: =IF(ISERROR(V051_20[[#This Row],[DISTANCIA POR CARTA]]/V051_20[[#This Row],[TIEMPO DE NAVEGACION]]),0,V051_20[[#This Row],[DISTANCIA POR CARTA]]/V051_20[[#This Row],[TIEMPO DE NAVEGACION]]) -> 0 | L6: 0.20833333 | M6: 0.052083333 | N6: 0.052083333 | O6: =SUM(V051_20[[#This Row],[MPAL]:[CALDERA]]) -> 0.3125 | Q6: =(Q4-V051_20[[#This Row],[TOTAL ]])+V051_20[[#This Row],[FAENA]] -> 82.6875 | R6: 0 | S6: 0 | T6: 0 | U6: 0 | V6: 0 | W6: =SUM(V051_20[[#This Row],[MPAL2]:[GI]]) -> 0 | Y6: =(Y4-V051_20[[#This Row],[TOTAL]])+V051_20[[#This Row],[FAENA2]] -> 20.9 | AB6: =(AB4-V051_20[[#This Row],[CYLINDER MP]])+V051_20[[#This Row],[FAENA EN LTS]] -> 100 | AE6: =(AE4-V051_20[[#This Row],[CARTER MP.]])+V051_20[[#This Row],[FAENA EN LTS2]] -> 100 | AH6: =(AH4-V051_20[[#This Row],[MOT AUX]])+V051_20[[#This Row],[FAENA EN LTS]] -> 100 | AK6: =(AK4-V051_20[[#This Row],[HIDRAULICO]])+V051_20[[#This Row],[FAENA EN LTS3]] -> 100
A7: V051-19 | B7: 43822 | C7: 0.33333333 | D7: =IF(V051_20[[#This Row],[FECHA]]-B6=1,((V051_20[[#This Row],[HORA]]-C6)*24)+24,(V051_20[[#This Row],[HORA]]-C6)*24) -> 15.5 | E7: FONDEADO | F7: FONDEADO | I7: =IF(ISERROR(V051_20[[#This Row],[DISTANCIA POR CARTA]]/V051_20[[#This Row],[TIEMPO DE NAVEGACION]]),0,V051_20[[#This Row],[DISTANCIA POR CARTA]]/V051_20[[#This Row],[TIEMPO DE NAVEGACION]]) -> 0 | L7: 0 | M7: 1.6145833 | N7: 1.6145833 | O7: =SUM(V051_20[[#This Row],[MPAL]:[CALDERA]]) -> 3.2291667 | Q7: =(Q6-V051_20[[#This Row],[TOTAL ]])+V051_20[[#This Row],[FAENA]] -> 79.458333 | R7: 0 | S7: 0 | T7: 0 | U7: 0 | V7: 0 | W7: =SUM(V051_20[[#This Row],[MPAL2]:[GI]]) -> 0 | Y7: =(Y6-V051_20[[#This Row],[TOTAL]])+V051_20[[#This Row],[FAENA2]] -> 20.9 | AB7: =(AB6-V051_20[[#This Row],[CYLINDER MP]])+V051_20[[#This Row],[FAENA EN LTS]] -> 100 | AE7: =(AE6-V051_20[[#This Row],[CARTER MP.]])+V051_20[[#This Row],[FAENA EN LTS2]] -> 100 | AH7: =(AH6-V051_20[[#This Row],[MOT AUX]])+V051_20[[#This Row],[FAENA EN LTS]] -> 100 | AK7: =(AK6-V051_20[[#This Row],[HIDRAULICO]])+V051_20[[#This Row],[FAENA EN LTS3]] -> 100
A8: V051-19 | B8: 43822 | C8: 0.42916667 | D8: =IF(V051_20[[#This Row],[FECHA]]-B7=1,((V051_20[[#This Row],[HORA]]-C7)*24)+24,(V051_20[[#This Row],[HORA]]-C7)*24) -> 2.3 | E8: FONDEADO | F8: ANCLA ARRIBA | I8: =IF(ISERROR(V051_20[[#This Row],[DISTANCIA POR CARTA]]/V051_20[[#This Row],[TIEMPO DE NAVEGACION]]),0,V051_20[[#This Row],[DISTANCIA POR CARTA]]/V051_20[[#This Row],[TIEMPO DE NAVEGACION]]) -> 0 | L8: 0 | M8: 0.23958333 | N8: 0.23958333 | O8: =SUM(V051_20[[#This Row],[MPAL]:[CALDERA]]) -> 0.47916667 | Q8: =(Q7-V051_20[[#This Row],[TOTAL ]])+V051_20[[#This Row],[FAENA]] -> 78.979167 | R8: 0 | S8: 0 | T8: 0 | U8: 0 | V8: 0 | W8: =SUM(V051_20[[#This Row],[MPAL2]:[GI]]) -> 0 | Y8: =(Y7-V051_20[[#This Row],[TOTAL]])+V051_20[[#This Row],[FAENA2]] -> 20.9 | AB8: =(AB7-V051_20[[#This Row],[CYLINDER MP]])+V051_20[[#This Row],[FAENA EN LTS]] -> 100 | AE8: =(AE7-V051_20[[#This Row],[CARTER MP.]])+V051_20[[#This Row],[FAENA EN LTS2]] -> 100 | AH8: =(AH7-V051_20[[#This Row],[MOT AUX]])+V051_20[[#This Row],[FAENA EN LTS]] -> 100 | AK8: =(AK7-V051_20[[#This Row],[HIDRAULICO]])+V051_20[[#This Row],[FAENA EN LTS3]] -> 100
A9: V051-19 | B9: 43822 | C9: 0.49166667 | D9: =IF(V051_20[[#This Row],[FECHA]]-B8=1,((V051_20[[#This Row],[HORA]]-C8)*24)+24,(V051_20[[#This Row],[HORA]]-C8)*24) -> 1.5 | E9: MANIOBRA | F9: INICIO MANIOBRA | I9: =IF(ISERROR(V051_20[[#This Row],[DISTANCIA POR CARTA]]/V051_20[[#This Row],[TIEMPO DE NAVEGACION]]),0,V051_20[[#This Row],[DISTANCIA POR CARTA]]/V051_20[[#This Row],[TIEMPO DE NAVEGACION]]) -> 0 | L9: 0 | M9: 0.15625 | N9: 0.15625 | O9: =SUM(V051_20[[#This Row],[MPAL]:[CALDERA]]) -> 0.3125 | Q9: =(Q8-V051_20[[#This Row],[TOTAL ]])+V051_20[[#This Row],[FAENA]] -> 78.666667 | R9: 0 | S9: 0 | T9: 0 | U9: 0 | V9: 0 | W9: =SUM(V051_20[[#This Row],[MPAL2]:[GI]]) -> 0 | Y9: =(Y8-V051_20[[#This Row],[TOTAL]])+V051_20[[#This Row],[FAENA2]] -> 20.9 | AB9: =(AB8-V051_20[[#This Row],[CYLINDER MP]])+V051_20[[#This Row],[FAENA EN LTS]] -> 100 | AE9: =(AE8-V051_20[[#This Row],[CARTER MP.]])+V051_20[[#This Row],[FAENA EN LTS2]] -> 100 | AH9: =(AH8-V051_20[[#This Row],[MOT AUX]])+V051_20[[#This Row],[FAENA EN LTS]] -> 100 | AK9: =(AK8-V051_20[[#This Row],[HIDRAULICO]])+V051_20[[#This Row],[FAENA EN LTS3]] -> 100
A10: V051-19 | B10: 43822 | C10: 0.525 | D10: =IF(V051_20[[#This Row],[FECHA]]-B9=1,((V051_20[[#This Row],[HORA]]-C9)*24)+24,(V051_20[[#This Row],[HORA]]-C9)*24) -> 0.8 | E10: MANIOBRA | F10: TCM | I10: =IF(ISERROR(V051_20[[#This Row],[DISTANCIA POR CARTA]]/V051_20[[#This Row],[TIEMPO DE NAVEGACION]]),0,V051_20[[#This Row],[DISTANCIA POR CARTA]]/V051_20[[#This Row],[TIEMPO DE NAVEGACION]]) -> 0 | L10: 0.33333333 | M10: 0.083333333 | N10: 0.083333333 | O10: =SUM(V051_20[[#This Row],[MPAL]:[CALDERA]]) -> 0.5 | Q10: =(Q9-V051_20[[#This Row],[TOTAL ]])+V051_20[[#This Row],[FAENA]] -> 78.166667 | R10: 0 | S10: 0 | T10: 0 | U10: 0 | V10: 0 | W10: =SUM(V051_20[[#This Row],[MPAL2]:[GI]]) -> 0 | Y10: =(Y9-V051_20[[#This Row],[TOTAL]])+V051_20[[#This Row],[FAENA2]] -> 20.9 | AB10: =(AB9-V051_20[[#This Row],[CYLINDER MP]])+V051_20[[#This Row],[FAENA EN LTS]] -> 100 | AE10: =(AE9-V051_20[[#This Row],[CARTER MP.]])+V051_20[[#This Row],[FAENA EN LTS2]] -> 100 | AH10: =(AH9-V051_20[[#This Row],[MOT AUX]])+V051_20[[#This Row],[FAENA EN LTS]] -> 100 | AK10: =(AK9-V051_20[[#This Row],[HIDRAULICO]])+V051_20[[#This Row],[FAENA EN LTS3]] -> 100
A11: V051-19 | B11: 43823 | C11: 0.33333333 | D11: =IF(V051_20[[#This Row],[FECHA]]-B10=1,((V051_20[[#This Row],[HORA]]-C10)*24)+24,(V051_20[[#This Row],[HORA]]-C10)*24) -> 19.4 | E11: OTRAS ACT. | F11: CARGANDO | I11: =IF(ISERROR(V051_20[[#This Row],[DISTANCIA POR CARTA]]/V051_20[[#This Row],[TIEMPO DE NAVEGACION]]),0,V051_20[[#This Row],[DISTANCIA POR CARTA]]/V051_20[[#This Row],[TIEMPO DE NAVEGACION]]) -> 0 | L11: 0 | M11: 2.0208333 | N11: 2.0208333 | O11: =SUM(V051_20[[#This Row],[MPAL]:[CALDERA]]) -> 4.0416667 | Q11: =(Q10-V051_20[[#This Row],[TOTAL ]])+V051_20[[#This Row],[FAENA]] -> 74.125 | R11: 0 | S11: 0.1 | T11: 0 | U11: 0 | V11: 0 | W11: =SUM(V051_20[[#This Row],[MPAL2]:[GI]]) -> 0.1 | Y11: =(Y10-V051_20[[#This Row],[TOTAL]])+V051_20[[#This Row],[FAENA2]] -> 20.8 | AB11: =(AB10-V051_20[[#This Row],[CYLINDER MP]])+V051_20[[#This Row],[FAENA EN LTS]] -> 100 | AE11: =(AE10-V051_20[[#This Row],[CARTER MP.]])+V051_20[[#This Row],[FAENA EN LTS2]] -> 100 | AH11: =(AH10-V051_20[[#This Row],[MOT AUX]])+V051_20[[#This Row],[FAENA EN LTS]] -> 100 | AK11: =(AK10-V051_20[[#This Row],[HIDRAULICO]])+V051_20[[#This Row],[FAENA EN LTS3]] -> 100
A12: V051-19 | B12: 43824 | C12: 0.125 | D12: =IF(V051_20[[#This Row],[FECHA]]-B11=1,((V051_20[[#This Row],[HORA]]-C11)*24)+24,(V051_20[[#This Row],[HORA]]-C11)*24) -> 19 | E12: CARGANDO | F12: TERMINO CARGA | I12: =IF(ISERROR(V051_20[[#This Row],[DISTANCIA POR CARTA]]/V051_20[[#This Row],[TIEMPO DE NAVEGACION]]),0,V051_20[[#This Row],[DISTANCIA POR CARTA]]/V051_20[[#This Row],[TIEMPO DE NAVEGACION]]) -> 0 | L12: 0 | M12: 1.9791667 | N12: 1.9791667 | O12: =SUM(V051_20[[#This Row],[MPAL]:[CALDERA]]) -> 3.9583333 | Q12: =(Q11-V051_20[[#This Row],[TOTAL ]])+V051_20[[#This Row],[FAENA]] -> 70.166667 | R12: 0 | S12: 0 | T12: 0 | U12: 0 | V12: 0 | W12: =SUM(V051_20[[#This Row],[MPAL2]:[GI]]) -> 0 | Y12: =(Y11-V051_20[[#This Row],[TOTAL]])+V051_20[[#This Row],[FAENA2]] -> 20.8 | AB12: =(AB11-V051_20[[#This Row],[CYLINDER MP]])+V051_20[[#This Row],[FAENA EN LTS]] -> 100 | AE12: =(AE11-V051_20[[#This Row],[CARTER MP.]])+V051_20[[#This Row],[FAENA EN LTS2]] -> 100 | AH12: =(AH11-V051_20[[#This Row],[MOT AUX]])+V051_20[[#This Row],[FAENA EN LTS]] -> 100 | AK12: =(AK11-V051_20[[#This Row],[HIDRAULICO]])+V051_20[[#This Row],[FAENA EN LTS3]] -> 100
A13: V051-19 | B13: 43824 | C13: 0.28333333 | D13: =IF(V051_20[[#This Row],[FECHA]]-B12=1,((V051_20[[#This Row],[HORA]]-C12)*24)+24,(V051_20[[#This Row],[HORA]]-C12)*24) -> 3.8 | E13: OTRAS ACT. | F13: INICIO MANIOBRA | I13: =IF(ISERROR(V051_20[[#This Row],[DISTANCIA POR CARTA]]/V051_20[[#This Row],[TIEMPO DE NAVEGACION]]),0,V051_20[[#This Row],[DISTANCIA POR CARTA]]/V051_20[[#This Row],[TIEMPO DE NAVEGACION]]) -> 0 | L13: 0 | M13: 0.39583333 | N13: 0.39583333 | O13: =SUM(V051_20[[#This Row],[MPAL]:[CALDERA]]) -> 0.79166667 | Q13: =(Q12-V051_20[[#This Row],[TOTAL ]])+V051_20[[#This Row],[FAENA]] -> 69.375 | R13: 0 | S13: 0 | T13: 0 | U13: 0 | V13: 0 | W13: =SUM(V051_20[[#This Row],[MPAL2]:[GI]]) -> 0 | Y13: =(Y12-V051_20[[#This Row],[TOTAL]])+V051_20[[#This Row],[FAENA2]] -> 20.8 | AB13: =(AB12-V051_20[[#This Row],[CYLINDER MP]])+V051_20[[#This Row],[FAENA EN LTS]] -> 100 | AE13: =(AE12-V051_20[[#This Row],[CARTER MP.]])+V051_20[[#This Row],[FAENA EN LTS2]] -> 100 | AH13: =(AH12-V051_20[[#This Row],[MOT AUX]])+V051_20[[#This Row],[FAENA EN LTS]] -> 100 | AK13: =(AK12-V051_20[[#This Row],[HIDRAULICO]])+V051_20[[#This Row],[FAENA EN LTS3]] -> 100
A14: V051-19 | B14: 43824 | C14: 0.30416667 | D14: =IF(V051_20[[#This Row],[FECHA]]-B13=1,((V051_20[[#This Row],[HORA]]-C13)*24)+24,(V051_20[[#This Row],[HORA]]-C13)*24) -> 0.5 | E14: MANIOBRA | F14: TCM | I14: =IF(ISERROR(V051_20[[#This Row],[DISTANCIA POR CARTA]]/V051_20[[#This Row],[TIEMPO DE NAVEGACION]]),0,V051_20[[#This Row],[DISTANCIA POR CARTA]]/V051_20[[#This Row],[TIEMPO DE NAVEGACION]]) -> 0 | L14: 0.20833333 | M14: 0.052083333 | N14: 0.052083333 | O14: =SUM(V051_20[[#This Row],[MPAL]:[CALDERA]]) -> 0.3125 | Q14: =(Q13-V051_20[[#This Row],[TOTAL ]])+V051_20[[#This Row],[FAENA]] -> 69.0625 | R14: 0 | S14: 0 | T14: 0 | U14: 0 | V14: 0 | W14: =SUM(V051_20[[#This Row],[MPAL2]:[GI]]) -> 0 | Y14: =(Y13-V051_20[[#This Row],[TOTAL]])+V051_20[[#This Row],[FAENA2]] -> 20.8 | AB14: =(AB13-V051_20[[#This Row],[CYLINDER MP]])+V051_20[[#This Row],[FAENA EN LTS]] -> 100 | AE14: =(AE13-V051_20[[#This Row],[CARTER MP.]])+V051_20[[#This Row],[FAENA EN LTS2]] -> 100 | AH14: =(AH13-V051_20[[#This Row],[MOT AUX]])+V051_20[[#This Row],[FAENA EN LTS]] -> 100 | AK14: =(AK13-V051_20[[#This Row],[HIDRAULICO]])+V051_20[[#This Row],[FAENA EN LTS3]] -> 100
A15: V051-19 | B15: 43824 | C15: 0.33333333 | D15: =IF(V051_20[[#This Row],[FECHA]]-B14=1,((V051_20[[#This Row],[HORA]]-C14)*24)+24,(V051_20[[#This Row],[HORA]]-C14)*24) -> 0.7 | E15: MANIOBRA | F15: ZARPE. IVM | I15: =IF(ISERROR(V051_20[[#This Row],[DISTANCIA POR CARTA]]/V051_20[[#This Row],[TIEMPO DE NAVEGACION]]),0,V051_20[[#This Row],[DISTANCIA POR CARTA]]/V051_20[[#This Row],[TIEMPO DE NAVEGACION]]) -> 0 | L15: 0.72916667 | M15: 0.072916667 | N15: 0.072916667 | O15: =SUM(V051_20[[#This Row],[MPAL]:[CALDERA]]) -> 0.875 | Q15: =(Q14-V051_20[[#This Row],[TOTAL ]])+V051_20[[#This Row],[FAENA]] -> 68.1875 | R15: 0 | S15: 0 | T15: 0 | U15: 0 | V15: 0 | W15: =SUM(V051_20[[#This Row],[MPAL2]:[GI]]) -> 0 | Y15: =(Y14-V051_20[[#This Row],[TOTAL]])+V051_20[[#This Row],[FAENA2]] -> 20.8 | AB15: =(AB14-V051_20[[#This Row],[CYLINDER MP]])+V051_20[[#This Row],[FAENA EN LTS]] -> 100 | AE15: =(AE14-V051_20[[#This Row],[CARTER MP.]])+V051_20[[#This Row],[FAENA EN LTS2]] -> 100 | AH15: =(AH14-V051_20[[#This Row],[MOT AUX]])+V051_20[[#This Row],[FAENA EN LTS]] -> 100 | AK15: =(AK14-V051_20[[#This Row],[HIDRAULICO]])+V051_20[[#This Row],[FAENA EN LTS3]] -> 100
A16: V051-19 | B16: 43824 | C16: 0.77916667 | D16: =IF(V051_20[[#This Row],[FECHA]]-B15=1,((V051_20[[#This Row],[HORA]]-C15)*24)+24,(V051_20[[#This Row],[HORA]]-C15)*24) -> 10.7 | E16: NAVEGANDO CON CARGA | F16: ARRIBO PISCO | I16: =IF(ISERROR(V051_20[[#This Row],[DISTANCIA POR CARTA]]/V051_20[[#This Row],[TIEMPO DE NAVEGACION]]),0,V051_20[[#This Row],[DISTANCIA POR CARTA]]/V051_20[[#This Row],[TIEMPO DE NAVEGACION]]) -> 0 | L16: 11.145833 | M16: 1.1145833 | N16: 1.1145833 | O16: =SUM(V051_20[[#This Row],[MPAL]:[CALDERA]]) -> 13.375 | Q16: =(Q15-V051_20[[#This Row],[TOTAL ]])+V051_20[[#This Row],[FAENA]] -> 54.8125 | R16: 0 | S16: 0 | T16: 0 | U16: 0 | V16: 0 | W16: =SUM(V051_20[[#This Row],[MPAL2]:[GI]]) -> 0 | Y16: =(Y15-V051_20[[#This Row],[TOTAL]])+V051_20[[#This Row],[FAENA2]] -> 20.8 | AB16: =(AB15-V051_20[[#This Row],[CYLINDER MP]])+V051_20[[#This Row],[FAENA EN LTS]] -> 100 | AE16: =(AE15-V051_20[[#This Row],[CARTER MP.]])+V051_20[[#This Row],[FAENA EN LTS2]] -> 100 | AH16: =(AH15-V051_20[[#This Row],[MOT AUX]])+V051_20[[#This Row],[FAENA EN LTS]] -> 100 | AK16: =(AK15-V051_20[[#This Row],[HIDRAULICO]])+V051_20[[#This Row],[FAENA EN LTS3]] -> 100
A17: V051-19 | B17: 43824 | C17: 0.82083333 | D17: =IF(V051_20[[#This Row],[FECHA]]-B16=1,((V051_20[[#This Row],[HORA]]-C16)*24)+24,(V051_20[[#This Row],[HORA]]-C16)*24) -> 1 | E17: MANIOBRA | F17: FONDO PISCO | I17: =IF(ISERROR(V051_20[[#This Row],[DISTANCIA POR CARTA]]/V051_20[[#This Row],[TIEMPO DE NAVEGACION]]),0,V051_20[[#This Row],[DISTANCIA POR CARTA]]/V051_20[[#This Row],[TIEMPO DE NAVEGACION]]) -> 0 | L17: 0.41666667 | M17: 0.10416667 | N17: 0.10416667 | O17: =SUM(V051_20[[#This Row],[MPAL]:[CALDERA]]) -> 0.625 | Q17: =(Q16-V051_20[[#This Row],[TOTAL ]])+V051_20[[#This Row],[FAENA]] -> 54.1875 | R17: 0 | S17: 0.1 | T17: 0 | U17: 0 | V17: 0 | W17: =SUM(V051_20[[#This Row],[MPAL2]:[GI]]) -> 0.1 | Y17: =(Y16-V051_20[[#This Row],[TOTAL]])+V051_20[[#This Row],[FAENA2]] -> 20.7 | AB17: =(AB16-V051_20[[#This Row],[CYLINDER MP]])+V051_20[[#This Row],[FAENA EN LTS]] -> 100 | AE17: =(AE16-V051_20[[#This Row],[CARTER MP.]])+V051_20[[#This Row],[FAENA EN LTS2]] -> 100 | AH17: =(AH16-V051_20[[#This Row],[MOT AUX]])+V051_20[[#This Row],[FAENA EN LTS]] -> 100 | AK17: =(AK16-V051_20[[#This Row],[HIDRAULICO]])+V051_20[[#This Row],[FAENA EN LTS3]] -> 100
A18: V051-19 | B18: 43825 | C18: 0.33333333 | D18: =IF(V051_20[[#This Row],[FECHA]]-B17=1,((V051_20[[#This Row],[HORA]]-C17)*24)+24,(V051_20[[#This Row],[HORA]]-C17)*24) -> 12.3 | E18: FONDEADO | F18: FONDEADO | I18: =IF(ISERROR(V051_20[[#This Row],[DISTANCIA POR CARTA]]/V051_20[[#This Row],[TIEMPO DE NAVEGACION]]),0,V051_20[[#This Row],[DISTANCIA POR CARTA]]/V051_20[[#This Row],[TIEMPO DE NAVEGACION]]) -> 0 | L18: 0 | M18: 1.28125 | N18: 1.28125 | O18: =SUM(V051_20[[#This Row],[MPAL]:[CALDERA]]) -> 2.5625 | Q18: =(Q17-V051_20[[#This Row],[TOTAL ]])+V051_20[[#This Row],[FAENA]] -> 51.625 | R18: 0 | S18: 0 | T18: 0 | U18: 0 | V18: 0 | W18: =SUM(V051_20[[#This Row],[MPAL2]:[GI]]) -> 0 | Y18: =(Y17-V051_20[[#This Row],[TOTAL]])+V051_20[[#This Row],[FAENA2]] -> 20.7 | AB18: =(AB17-V051_20[[#This Row],[CYLINDER MP]])+V051_20[[#This Row],[FAENA EN LTS]] -> 100 | AE18: =(AE17-V051_20[[#This Row],[CARTER MP.]])+V051_20[[#This Row],[FAENA EN LTS2]] -> 100 | AH18: =(AH17-V051_20[[#This Row],[MOT AUX]])+V051_20[[#This Row],[FAENA EN LTS]] -> 100 | AK18: =(AK17-V051_20[[#This Row],[HIDRAULICO]])+V051_20[[#This Row],[FAENA EN LTS3]] -> 100
... A41: V051-19 | B41: 43830 | C41: 0.58333333 | D41: =IF(V051_20[[#This Row],[FECHA]]-B40=1,((V051_20[[#This Row],[HORA]]-C40)*24)+24,(V051_20[[#This Row],[HORA]]-C40)*24) -> 0.5 | E41: NAVEGANDO CON CARGA | F41: ARRIBO AREA 12 | I41: =IF(ISERROR(V051_20[[#This Row],[DISTANCIA POR CARTA]]/V051_20[[#This Row],[TIEMPO DE NAVEGACION]]),0,V051_20[[#This Row],[DISTANCIA POR CARTA]]/V051_20[[#This Row],[TIEMPO DE NAVEGACION]]) -> 0 | L41: 0 | M41: 0 | N41: 0 | O41: =SUM(V051_20[[#This Row],[MPAL]:[CALDERA]]) -> 0 | Q41: =(Q40-V051_20[[#This Row],[TOTAL ]])+V051_20[[#This Row],[FAENA]] -> 0.005 | R41: 0.42 | S41: 0.1 | T41: 0.1 | U41: 0 | V41: 0 | W41: =SUM(V051_20[[#This Row],[MPAL2]:[GI]]) -> 0.62 | Y41: =(Y40-V051_20[[#This Row],[TOTAL]])+V051_20[[#This Row],[FAENA2]] -> 17.23 | AB41: =(AB40-V051_20[[#This Row],[CYLINDER MP]])+V051_20[[#This Row],[FAENA EN LTS]] -> 100 | AE41: =(AE40-V051_20[[#This Row],[CARTER MP.]])+V051_20[[#This Row],[FAENA EN LTS2]] -> 100 | AH41: =(AH40-V051_20[[#This Row],[MOT AUX]])+V051_20[[#This Row],[FAENA EN LTS]] -> 100 | AK41: =(AK40-V051_20[[#This Row],[HIDRAULICO]])+V051_20[[#This Row],[FAENA EN LTS3]] -> 100
A42: V051-19 | B42: 43830 | C42: 0.6125 | D42: =IF(V051_20[[#This Row],[FECHA]]-B41=1,((V051_20[[#This Row],[HORA]]-C41)*24)+24,(V051_20[[#This Row],[HORA]]-C41)*24) -> 0.7 | E42: MANIOBRA | F42: FONDO AREA 12 | I42: =IF(ISERROR(V051_20[[#This Row],[DISTANCIA POR CARTA]]/V051_20[[#This Row],[TIEMPO DE NAVEGACION]]),0,V051_20[[#This Row],[DISTANCIA POR CARTA]]/V051_20[[#This Row],[TIEMPO DE NAVEGACION]]) -> 0 | L42: 0 | M42: 0 | N42: 0 | O42: =SUM(V051_20[[#This Row],[MPAL]:[CALDERA]]) -> 0 | Q42: =(Q41-V051_20[[#This Row],[TOTAL ]])+V051_20[[#This Row],[FAENA]] -> 0.005 | R42: 0.29 | S42: 0.1 | T42: 1.1 | U42: 0 | V42: 0 | W42: =SUM(V051_20[[#This Row],[MPAL2]:[GI]]) -> 1.49 | X42: 80 | Y42: =(Y41-V051_20[[#This Row],[TOTAL]])+V051_20[[#This Row],[FAENA2]] -> 95.74 | AB42: =(AB41-V051_20[[#This Row],[CYLINDER MP]])+V051_20[[#This Row],[FAENA EN LTS]] -> 100 | AE42: =(AE41-V051_20[[#This Row],[CARTER MP.]])+V051_20[[#This Row],[FAENA EN LTS2]] -> 100 | AH42: =(AH41-V051_20[[#This Row],[MOT AUX]])+V051_20[[#This Row],[FAENA EN LTS]] -> 100 | AK42: =(AK41-V051_20[[#This Row],[HIDRAULICO]])+V051_20[[#This Row],[FAENA EN LTS3]] -> 100
A43: V051-19 | B43: 43830 | C43: 0.95 | D43: =IF(V051_20[[#This Row],[FECHA]]-B42=1,((V051_20[[#This Row],[HORA]]-C42)*24)+24,(V051_20[[#This Row],[HORA]]-C42)*24) -> 8.1 | E43: OTRAS ACT. | F43: ANCLA ARRIBA | I43: =IF(ISERROR(V051_20[[#This Row],[DISTANCIA POR CARTA]]/V051_20[[#This Row],[TIEMPO DE NAVEGACION]]),0,V051_20[[#This Row],[DISTANCIA POR CARTA]]/V051_20[[#This Row],[TIEMPO DE NAVEGACION]]) -> 0 | L43: 0 | M43: 0 | N43: 0 | O43: =SUM(V051_20[[#This Row],[MPAL]:[CALDERA]]) -> 0 | Q43: =(Q42-V051_20[[#This Row],[TOTAL ]])+V051_20[[#This Row],[FAENA]] -> 0.005 | R43: 0 | S43: 0.2 | T43: 0.1 | U43: 0 | V43: 0 | W43: =SUM(V051_20[[#This Row],[MPAL2]:[GI]]) -> 0.3 | Y43: =(Y42-V051_20[[#This Row],[TOTAL]])+V051_20[[#This Row],[FAENA2]] -> 95.44 | AB43: =(AB42-V051_20[[#This Row],[CYLINDER MP]])+V051_20[[#This Row],[FAENA EN LTS]] -> 100 | AE43: =(AE42-V051_20[[#This Row],[CARTER MP.]])+V051_20[[#This Row],[FAENA EN LTS2]] -> 100 | AH43: =(AH42-V051_20[[#This Row],[MOT AUX]])+V051_20[[#This Row],[FAENA EN LTS]] -> 100 | AK43: =(AK42-V051_20[[#This Row],[HIDRAULICO]])+V051_20[[#This Row],[FAENA EN LTS3]] -> 100
A44: V051-19 | B44: 43830 | C44: 0.97916667 | D44: =IF(V051_20[[#This Row],[FECHA]]-B43=1,((V051_20[[#This Row],[HORA]]-C43)*24)+24,(V051_20[[#This Row],[HORA]]-C43)*24) -> 0.7 | E44: OTRAS ACT. | F44: ZARPE | I44: =IF(ISERROR(V051_20[[#This Row],[DISTANCIA POR CARTA]]/V051_20[[#This Row],[TIEMPO DE NAVEGACION]]),0,V051_20[[#This Row],[DISTANCIA POR CARTA]]/V051_20[[#This Row],[TIEMPO DE NAVEGACION]]) -> 0 | L44: 0 | M44: 0 | N44: 0 | O44: =SUM(V051_20[[#This Row],[MPAL]:[CALDERA]]) -> 0 | P44: 370 | Q44: =(Q43-V051_20[[#This Row],[TOTAL ]])+V051_20[[#This Row],[FAENA]] -> 370.005 | R44: 0.29 | S44: 0.1 | T44: 0.1 | U44: 0 | V44: 0 | W44: =SUM(V051_20[[#This Row],[MPAL2]:[GI]]) -> 0.49 | Y44: =(Y43-V051_20[[#This Row],[TOTAL]])+V051_20[[#This Row],[FAENA2]] -> 94.95 | AB44: =(AB43-V051_20[[#This Row],[CYLINDER MP]])+V051_20[[#This Row],[FAENA EN LTS]] -> 100 | AE44: =(AE43-V051_20[[#This Row],[CARTER MP.]])+V051_20[[#This Row],[FAENA EN LTS2]] -> 100 | AH44: =(AH43-V051_20[[#This Row],[MOT AUX]])+V051_20[[#This Row],[FAENA EN LTS]] -> 100 | AK44: =(AK43-V051_20[[#This Row],[HIDRAULICO]])+V051_20[[#This Row],[FAENA EN LTS3]] -> 100
A45: V051-20 | B45: 43831 | C45: 0.3 | D45: =IF(V051_20[[#This Row],[FECHA]]-B44=1,((V051_20[[#This Row],[HORA]]-C44)*24)+24,(V051_20[[#This Row],[HORA]]-C44)*24) -> 7.7 | E45: NAVEGANDO CON CARGA | F45: ARRIBO SUPE | G45: 91 | H45: 7.2 | I45: =IF(ISERROR(V051_20[[#This Row],[DISTANCIA POR CARTA]]/V051_20[[#This Row],[TIEMPO DE NAVEGACION]]),0,V051_20[[#This Row],[DISTANCIA POR CARTA]]/V051_20[[#This Row],[TIEMPO DE NAVEGACION]]) -> 12.638889 | J45: S2 | K45: 95 | L45: 0 | M45: 0 | N45: 0 | O45: =SUM(V051_20[[#This Row],[MPAL]:[CALDERA]]) -> 0 | Q45: =(Q44-V051_20[[#This Row],[TOTAL ]])+V051_20[[#This Row],[FAENA]] -> 370.005 | R45: 7.97 | S45: 0.89 | T45: 0.06 | U45: 0 | V45: 0 | W45: =SUM(V051_20[[#This Row],[MPAL2]:[GI]]) -> 8.92 | Y45: =(Y44-V051_20[[#This Row],[TOTAL]])+V051_20[[#This Row],[FAENA2]] -> 86.03 | AB45: =(AB44-V051_20[[#This Row],[CYLINDER MP]])+V051_20[[#This Row],[FAENA EN LTS]] -> 100 | AE45: =(AE44-V051_20[[#This Row],[CARTER MP.]])+V051_20[[#This Row],[FAENA EN LTS2]] -> 100 | AH45: =(AH44-V051_20[[#This Row],[MOT AUX]])+V051_20[[#This Row],[FAENA EN LTS]] -> 100 | AK45: =(AK44-V051_20[[#This Row],[HIDRAULICO]])+V051_20[[#This Row],[FAENA EN LTS3]] -> 100
A46: V051-19 | B46: 43831 | C46: 0.33333333 | D46: =IF(V051_20[[#This Row],[FECHA]]-B45=1,((V051_20[[#This Row],[HORA]]-C45)*24)+24,(V051_20[[#This Row],[HORA]]-C45)*24) -> 0.8 | E46: MANIOBRA | F46: SUPE | I46: =IF(ISERROR(V051_20[[#This Row],[DISTANCIA POR CARTA]]/V051_20[[#This Row],[TIEMPO DE NAVEGACION]]),0,V051_20[[#This Row],[DISTANCIA POR CARTA]]/V051_20[[#This Row],[TIEMPO DE NAVEGACION]]) -> 0 | L46: 0 | M46: 0 | N46: 0 | O46: =SUM(V051_20[[#This Row],[MPAL]:[CALDERA]]) -> 0 | Q46: =(Q45-V051_20[[#This Row],[TOTAL ]])+V051_20[[#This Row],[FAENA]] -> 370.005 | R46: 0.33 | S46: 0.08 | T46: 0.07 | U46: 0 | V46: 0 | W46: =SUM(V051_20[[#This Row],[MPAL2]:[GI]]) -> 0.48 | Y46: =(Y45-V051_20[[#This Row],[TOTAL]])+V051_20[[#This Row],[FAENA2]] -> 85.55 | AB46: =(AB45-V051_20[[#This Row],[CYLINDER MP]])+V051_20[[#This Row],[FAENA EN LTS]] -> 100 | AE46: =(AE45-V051_20[[#This Row],[CARTER MP.]])+V051_20[[#This Row],[FAENA EN LTS2]] -> 100 | AH46: =(AH45-V051_20[[#This Row],[MOT AUX]])+V051_20[[#This Row],[FAENA EN LTS]] -> 100 | AK46: =(AK45-V051_20[[#This Row],[HIDRAULICO]])+V051_20[[#This Row],[FAENA EN LTS3]] -> 100
A47: V051-19 | B47: 43831 | C47: 0.35 | D47: =IF(V051_20[[#This Row],[FECHA]]-B46=1,((V051_20[[#This Row],[HORA]]-C46)*24)+24,(V051_20[[#This Row],[HORA]]-C46)*24) -> 0.4 | E47: MANIOBRA | F47: INICIO MANIOBRA SUPE | I47: 0 | L47: 0 | M47: 0.041666667 | N47: 0.033333333 | O47: =SUM(V051_20[[#This Row],[MPAL]:[CALDERA]]) -> 0.075 | Q47: =(Q46-V051_20[[#This Row],[TOTAL ]])+V051_20[[#This Row],[FAENA]] -> 369.93 | R47: 0 | S47: 0 | T47: 0 | U47: 0 | V47: 0 | W47: =SUM(V051_20[[#This Row],[MPAL2]:[GI]]) -> 0 | Y47: =(Y46-V051_20[[#This Row],[TOTAL]])+V051_20[[#This Row],[FAENA2]] -> 85.55 | AB47: =(AB46-V051_20[[#This Row],[CYLINDER MP]])+V051_20[[#This Row],[FAENA EN LTS]] -> 100 | AE47: =(AE46-V051_20[[#This Row],[CARTER MP.]])+V051_20[[#This Row],[FAENA EN LTS2]] -> 100 | AH47: =(AH46-V051_20[[#This Row],[MOT AUX]])+V051_20[[#This Row],[FAENA EN LTS]] -> 100 | AK47: =(AK46-V051_20[[#This Row],[HIDRAULICO]])+V051_20[[#This Row],[FAENA EN LTS3]] -> 100
A48: V051-19 | B48: 43831 | C48: 0.3875 | D48: =IF(V051_20[[#This Row],[FECHA]]-B47=1,((V051_20[[#This Row],[HORA]]-C47)*24)+24,(V051_20[[#This Row],[HORA]]-C47)*24) -> 0.9 | E48: MANIOBRA | F48: TCM SUPE | I48: =IF(ISERROR(V051_20[[#This Row],[DISTANCIA POR CARTA]]/V051_20[[#This Row],[TIEMPO DE NAVEGACION]]),0,V051_20[[#This Row],[DISTANCIA POR CARTA]]/V051_20[[#This Row],[TIEMPO DE NAVEGACION]]) -> 0 | L48: 0.375 | M48: 0.09375 | N48: 0.075 | O48: =SUM(V051_20[[#This Row],[MPAL]:[CALDERA]]) -> 0.54375 | Q48: =(Q47-V051_20[[#This Row],[TOTAL ]])+V051_20[[#This Row],[FAENA]] -> 369.38625 | R48: 0 | S48: 0 | T48: 0 | U48: 0 | V48: 0 | W48: =SUM(V051_20[[#This Row],[MPAL2]:[GI]]) -> 0 | Y48: =(Y47-V051_20[[#This Row],[TOTAL]])+V051_20[[#This Row],[FAENA2]] -> 85.55 | AB48: =(AB47-V051_20[[#This Row],[CYLINDER MP]])+V051_20[[#This Row],[FAENA EN LTS]] -> 100 | AE48: =(AE47-V051_20[[#This Row],[CARTER MP.]])+V051_20[[#This Row],[FAENA EN LTS2]] -> 100 | AH48: =(AH47-V051_20[[#This Row],[MOT AUX]])+V051_20[[#This Row],[FAENA EN LTS]] -> 100 | AK48: =(AK47-V051_20[[#This Row],[HIDRAULICO]])+V051_20[[#This Row],[FAENA EN LTS3]] -> 100
A49: V051-19 | B49: 43831 | C49: 0.50416667 | D49: =IF(V051_20[[#This Row],[FECHA]]-B48=1,((V051_20[[#This Row],[HORA]]-C48)*24)+24,(V051_20[[#This Row],[HORA]]-C48)*24) -> 2.8 | E49: OTRAS ACT. | F49: INICIO DESCARGA SUPE | I49: =IF(ISERROR(V051_20[[#This Row],[DISTANCIA POR CARTA]]/V051_20[[#This Row],[TIEMPO DE NAVEGACION]]),0,V051_20[[#This Row],[DISTANCIA POR CARTA]]/V051_20[[#This Row],[TIEMPO DE NAVEGACION]]) -> 0 | L49: 0 | M49: 0.29166667 | N49: 0.23333333 | O49: =SUM(V051_20[[#This Row],[MPAL]:[CALDERA]]) -> 0.525 | Q49: =(Q48-V051_20[[#This Row],[TOTAL ]])+V051_20[[#This Row],[FAENA]] -> 368.86125 | R49: 0 | S49: 0 | T49: 0 | U49: 0 | V49: 0 | W49: =SUM(V051_20[[#This Row],[MPAL2]:[GI]]) -> 0 | Y49: =(Y48-V051_20[[#This Row],[TOTAL]])+V051_20[[#This Row],[FAENA2]] -> 85.55 | AB49: =(AB48-V051_20[[#This Row],[CYLINDER MP]])+V051_20[[#This Row],[FAENA EN LTS]] -> 100 | AE49: =(AE48-V051_20[[#This Row],[CARTER MP.]])+V051_20[[#This Row],[FAENA EN LTS2]] -> 100 | AH49: =(AH48-V051_20[[#This Row],[MOT AUX]])+V051_20[[#This Row],[FAENA EN LTS]] -> 100 | AK49: =(AK48-V051_20[[#This Row],[HIDRAULICO]])+V051_20[[#This Row],[FAENA EN LTS3]] -> 100
A50: V051-19 | B50: 43831 | C50: 0.95833333 | D50: =IF(V051_20[[#This Row],[FECHA]]-B49=1,((V051_20[[#This Row],[HORA]]-C49)*24)+24,(V051_20[[#This Row],[HORA]]-C49)*24) -> 10.9 | E50: DESCARGANDO | F50: TERMINO DESARGA SUPE | I50: =IF(ISERROR(V051_20[[#This Row],[DISTANCIA POR CARTA]]/V051_20[[#This Row],[TIEMPO DE NAVEGACION]]),0,V051_20[[#This Row],[DISTANCIA POR CARTA]]/V051_20[[#This Row],[TIEMPO DE NAVEGACION]]) -> 0 | L50: 0 | M50: 1.1354167 | N50: 0.90833333 | O50: =SUM(V051_20[[#This Row],[MPAL]:[CALDERA]]) -> 2.04375 | Q50: =(Q49-V051_20[[#This Row],[TOTAL ]])+V051_20[[#This Row],[FAENA]] -> 366.8175 | R50: 0 | S50: 0 | T50: 0 | U50: 0 | V50: 2.8 | W50: =SUM(V051_20[[#This Row],[MPAL2]:[GI]]) -> 2.8 | Y50: =(Y49-V051_20[[#This Row],[TOTAL]])+V051_20[[#This Row],[FAENA2]] -> 82.75 | AB50: =(AB49-V051_20[[#This Row],[CYLINDER MP]])+V051_20[[#This Row],[FAENA EN LTS]] -> 100 | AE50: =(AE49-V051_20[[#This Row],[CARTER MP.]])+V051_20[[#This Row],[FAENA EN LTS2]] -> 100 | AH50: =(AH49-V051_20[[#This Row],[MOT AUX]])+V051_20[[#This Row],[FAENA EN LTS]] -> 100 | AK50: =(AK49-V051_20[[#This Row],[HIDRAULICO]])+V051_20[[#This Row],[FAENA EN LTS3]] -> 100
A51: V051-19 | B51: 43832 | C51: 0.0875 | D51: =IF(V051_20[[#This Row],[FECHA]]-B50=1,((V051_20[[#This Row],[HORA]]-C50)*24)+24,(V051_20[[#This Row],[HORA]]-C50)*24) -> 3.1 | E51: OTRAS ACT. | F51: INICIO MANIOBRA ZARPE SUPE | I51: =IF(ISERROR(V051_20[[#This Row],[DISTANCIA POR CARTA]]/V051_20[[#This Row],[TIEMPO DE NAVEGACION]]),0,V051_20[[#This Row],[DISTANCIA POR CARTA]]/V051_20[[#This Row],[TIEMPO DE NAVEGACION]]) -> 0 | L51: 0 | M51: 0.32291667 | N51: 0.25833333 | O51: =SUM(V051_20[[#This Row],[MPAL]:[CALDERA]]) -> 0.58125 | Q51: =(Q50-V051_20[[#This Row],[TOTAL ]])+V051_20[[#This Row],[FAENA]] -> 366.23625 | R51: 0 | S51: 0 | T51: 0 | U51: 0 | V51: 0 | W51: =SUM(V051_20[[#This Row],[MPAL2]:[GI]]) -> 0 | Y51: =(Y50-V051_20[[#This Row],[TOTAL]])+V051_20[[#This Row],[FAENA2]] -> 82.75 | AB51: =(AB50-V051_20[[#This Row],[CYLINDER MP]])+V051_20[[#This Row],[FAENA EN LTS]] -> 100 | AE51: =(AE50-V051_20[[#This Row],[CARTER MP.]])+V051_20[[#This Row],[FAENA EN LTS2]] -> 100 | AH51: =(AH50-V051_20[[#This Row],[MOT AUX]])+V051_20[[#This Row],[FAENA EN LTS]] -> 100 | AK51: =(AK50-V051_20[[#This Row],[HIDRAULICO]])+V051_20[[#This Row],[FAENA EN LTS3]] -> 100
A52: V051-19 | B52: 43832 | C52: 0.1125 | D52: =IF(V051_20[[#This Row],[FECHA]]-B51=1,((V051_20[[#This Row],[HORA]]-C51)*24)+24,(V051_20[[#This Row],[HORA]]-C51)*24) -> 0.6 | E52: MANIOBRA | F52: ZARPE SUPE | I52: =IF(ISERROR(V051_20[[#This Row],[DISTANCIA POR CARTA]]/V051_20[[#This Row],[TIEMPO DE NAVEGACION]]),0,V051_20[[#This Row],[DISTANCIA POR CARTA]]/V051_20[[#This Row],[TIEMPO DE NAVEGACION]]) -> 0 | L52: 0.25 | M52: 0.0625 | N52: 0.05 | O52: =SUM(V051_20[[#This Row],[MPAL]:[CALDERA]]) -> 0.3625 | Q52: =(Q51-V051_20[[#This Row],[TOTAL ]])+V051_20[[#This Row],[FAENA]] -> 365.87375 | R52: 0 | S52: 0 | T52: 0 | U52: 0 | V52: 0 | W52: =SUM(V051_20[[#This Row],[MPAL2]:[GI]]) -> 0 | Y52: =(Y51-V051_20[[#This Row],[TOTAL]])+V051_20[[#This Row],[FAENA2]] -> 82.75 | AB52: =(AB51-V051_20[[#This Row],[CYLINDER MP]])+V051_20[[#This Row],[FAENA EN LTS]] -> 100 | AE52: =(AE51-V051_20[[#This Row],[CARTER MP.]])+V051_20[[#This Row],[FAENA EN LTS2]] -> 100 | AH52: =(AH51-V051_20[[#This Row],[MOT AUX]])+V051_20[[#This Row],[FAENA EN LTS]] -> 100 | AK52: =(AK51-V051_20[[#This Row],[HIDRAULICO]])+V051_20[[#This Row],[FAENA EN LTS3]] -> 100
A53: V051-19 | B53: 43832 | C53: 0.33333333 | D53: =IF(V051_20[[#This Row],[FECHA]]-B52=1,((V051_20[[#This Row],[HORA]]-C52)*24)+24,(V051_20[[#This Row],[HORA]]-C52)*24) -> 5.3 | E53: NAVEGANDO CON CARGA | F53: NAVEGANDO A ETEN | I53: =IF(ISERROR(V051_20[[#This Row],[DISTANCIA POR CARTA]]/V051_20[[#This Row],[TIEMPO DE NAVEGACION]]),0,V051_20[[#This Row],[DISTANCIA POR CARTA]]/V051_20[[#This Row],[TIEMPO DE NAVEGACION]]) -> 0 | J53: S2 | K53: 95 | L53: 5.5208333 | M53: 0.55208333 | N53: 0.44166667 | O53: =SUM(V051_20[[#This Row],[MPAL]:[CALDERA]]) -> 6.5145833 | Q53: =(Q52-V051_20[[#This Row],[TOTAL ]])+V051_20[[#This Row],[FAENA]] -> 359.35917 | R53: 0 | S53: 0 | T53: 0 | U53: 0 | V53: 0 | W53: =SUM(V051_20[[#This Row],[MPAL2]:[GI]]) -> 0 | Y53: =(Y52-V051_20[[#This Row],[TOTAL]])+V051_20[[#This Row],[FAENA2]] -> 82.75 | AB53: =(AB52-V051_20[[#This Row],[CYLINDER MP]])+V051_20[[#This Row],[FAENA EN LTS]] -> 100 | AE53: =(AE52-V051_20[[#This Row],[CARTER MP.]])+V051_20[[#This Row],[FAENA EN LTS2]] -> 100 | AH53: =(AH52-V051_20[[#This Row],[MOT AUX]])+V051_20[[#This Row],[FAENA EN LTS]] -> 100 | AK53: =(AK52-V051_20[[#This Row],[HIDRAULICO]])+V051_20[[#This Row],[FAENA EN LTS3]] -> 100
A54: V051-19 | B54: 43833 | C54: 0.095833333 | D54: =IF(V051_20[[#This Row],[FECHA]]-B53=1,((V051_20[[#This Row],[HORA]]-C53)*24)+24,(V051_20[[#This Row],[HORA]]-C53)*24) -> 18.3 | E54: NAVEGANDO CON CARGA | F54: ARRIBO ETEN | G54: 266 | H54: 23.6 | I54: =IF(ISERROR(V051_20[[#This Row],[DISTANCIA POR CARTA]]/V051_20[[#This Row],[TIEMPO DE NAVEGACION]]),0,V051_20[[#This Row],[DISTANCIA POR CARTA]]/V051_20[[#This Row],[TIEMPO DE NAVEGACION]]) -> 11.271186 | J54: S 2 | K54: 95 | L54: 19.0625 | M54: 1.90625 | N54: 1.525 | O54: =SUM(V051_20[[#This Row],[MPAL]:[CALDERA]]) -> 22.49375 | Q54: =(Q53-V051_20[[#This Row],[TOTAL ]])+V051_20[[#This Row],[FAENA]] -> 336.86542 | R54: 0 | S54: 0 | T54: 0 | U54: 0 | V54: 0 | W54: =SUM(V051_20[[#This Row],[MPAL2]:[GI]]) -> 0 | Y54: =(Y53-V051_20[[#This Row],[TOTAL]])+V051_20[[#This Row],[FAENA2]] -> 82.75 | AB54: =(AB53-V051_20[[#This Row],[CYLINDER MP]])+V051_20[[#This Row],[FAENA EN LTS]] -> 100 | AE54: =(AE53-V051_20[[#This Row],[CARTER MP.]])+V051_20[[#This Row],[FAENA EN LTS2]] -> 100 | AH54: =(AH53-V051_20[[#This Row],[MOT AUX]])+V051_20[[#This Row],[FAENA EN LTS]] -> 100 | AK54: =(AK53-V051_20[[#This Row],[HIDRAULICO]])+V051_20[[#This Row],[FAENA EN LTS3]] -> 100
A55: V051-19 | B55: 43833 | C55: 0.11666667 | D55: =IF(V051_20[[#This Row],[FECHA]]-B54=1,((V051_20[[#This Row],[HORA]]-C54)*24)+24,(V051_20[[#This Row],[HORA]]-C54)*24) -> 0.5 | E55: MANIOBRA | F55: TCM FONDEADO ETEN | I55: =IF(ISERROR(V051_20[[#This Row],[DISTANCIA POR CARTA]]/V051_20[[#This Row],[TIEMPO DE NAVEGACION]]),0,V051_20[[#This Row],[DISTANCIA POR CARTA]]/V051_20[[#This Row],[TIEMPO DE NAVEGACION]]) -> 0 | L55: 0.20833333 | M55: 0.052083333 | N55: 0.041666667 | O55: =SUM(V051_20[[#This Row],[MPAL]:[CALDERA]]) -> 0.30208333 | Q55: =(Q54-V051_20[[#This Row],[TOTAL ]])+V051_20[[#This Row],[FAENA]] -> 336.56333 | R55: 0 | S55: 0 | T55: 0 | U55: 0 | V55: 0 | W55: =SUM(V051_20[[#This Row],[MPAL2]:[GI]]) -> 0 | Y55: =(Y54-V051_20[[#This Row],[TOTAL]])+V051_20[[#This Row],[FAENA2]] -> 82.75 | AB55: =(AB54-V051_20[[#This Row],[CYLINDER MP]])+V051_20[[#This Row],[FAENA EN LTS]] -> 100 | AE55: =(AE54-V051_20[[#This Row],[CARTER MP.]])+V051_20[[#This Row],[FAENA EN LTS2]] -> 100 | AH55: =(AH54-V051_20[[#This Row],[MOT AUX]])+V051_20[[#This Row],[FAENA EN LTS]] -> 100 | AK55: =(AK54-V051_20[[#This Row],[HIDRAULICO]])+V051_20[[#This Row],[FAENA EN LTS3]] -> 100
A56: V051-19 | B56: 43833 | C56: 0.33333333 | D56: =IF(V051_20[[#This Row],[FECHA]]-B55=1,((V051_20[[#This Row],[HORA]]-C55)*24)+24,(V051_20[[#This Row],[HORA]]-C55)*24) -> 5.2 | E56: FONDEADO | F56: ETEN | I56: =IF(ISERROR(V051_20[[#This Row],[DISTANCIA POR CARTA]]/V051_20[[#This Row],[TIEMPO DE NAVEGACION]]),0,V051_20[[#This Row],[DISTANCIA POR CARTA]]/V051_20[[#This Row],[TIEMPO DE NAVEGACION]]) -> 0 | L56: 0 | M56: 0.54166667 | N56: 0.43333333 | O56: =SUM(V051_20[[#This Row],[MPAL]:[CALDERA]]) -> 0.975 | Q56: =(Q55-V051_20[[#This Row],[TOTAL ]])+V051_20[[#This Row],[FAENA]] -> 335.58833 | R56: 0 | S56: 0 | T56: 0 | U56: 0 | V56: 0 | W56: =SUM(V051_20[[#This Row],[MPAL2]:[GI]]) -> 0 | Y56: =(Y55-V051_20[[#This Row],[TOTAL]])+V051_20[[#This Row],[FAENA2]] -> 82.75 | AB56: =(AB55-V051_20[[#This Row],[CYLINDER MP]])+V051_20[[#This Row],[FAENA EN LTS]] -> 100 | AE56: =(AE55-V051_20[[#This Row],[CARTER MP.]])+V051_20[[#This Row],[FAENA EN LTS2]] -> 100 | AH56: =(AH55-V051_20[[#This Row],[MOT AUX]])+V051_20[[#This Row],[FAENA EN LTS]] -> 100 | AK56: =(AK55-V051_20[[#This Row],[HIDRAULICO]])+V051_20[[#This Row],[FAENA EN LTS3]] -> 100
A57: V051-19 | B57: 43834 | C57: 0.33333333 | D57: =IF(V051_20[[#This Row],[FECHA]]-B56=1,((V051_20[[#This Row],[HORA]]-C56)*24)+24,(V051_20[[#This Row],[HORA]]-C56)*24) -> 24 | E57: FONDEADO | F57: ETEN | I57: =IF(ISERROR(V051_20[[#This Row],[DISTANCIA POR CARTA]]/V051_20[[#This Row],[TIEMPO DE NAVEGACION]]),0,V051_20[[#This Row],[DISTANCIA POR CARTA]]/V051_20[[#This Row],[TIEMPO DE NAVEGACION]]) -> 0 | L57: 0 | M57: 2.5 | N57: 2 | O57: =SUM(V051_20[[#This Row],[MPAL]:[CALDERA]]) -> 4.5 | Q57: =(Q56-V051_20[[#This Row],[TOTAL ]])+V051_20[[#This Row],[FAENA]] -> 331.08833 | R57: 0 | S57: 0 | T57: 0 | U57: 0 | V57: 0 | W57: =SUM(V051_20[[#This Row],[MPAL2]:[GI]]) -> 0 | Y57: =(Y56-V051_20[[#This Row],[TOTAL]])+V051_20[[#This Row],[FAENA2]] -> 82.75 | AB57: =(AB56-V051_20[[#This Row],[CYLINDER MP]])+V051_20[[#This Row],[FAENA EN LTS]] -> 100 | AE57: =(AE56-V051_20[[#This Row],[CARTER MP.]])+V051_20[[#This Row],[FAENA EN LTS2]] -> 100 | AH57: =(AH56-V051_20[[#This Row],[MOT AUX]])+V051_20[[#This Row],[FAENA EN LTS]] -> 100 | AK57: =(AK56-V051_20[[#This Row],[HIDRAULICO]])+V051_20[[#This Row],[FAENA EN LTS3]] -> 100
A58: V051-19 | B58: 43835 | C58: 0.33333333 | D58: =IF(V051_20[[#This Row],[FECHA]]-B57=1,((V051_20[[#This Row],[HORA]]-C57)*24)+24,(V051_20[[#This Row],[HORA]]-C57)*24) -> 24 | E58: FONDEADO | F58: ETEN | I58: =IF(ISERROR(V051_20[[#This Row],[DISTANCIA POR CARTA]]/V051_20[[#This Row],[TIEMPO DE NAVEGACION]]),0,V051_20[[#This Row],[DISTANCIA POR CARTA]]/V051_20[[#This Row],[TIEMPO DE NAVEGACION]]) -> 0 | L58: 0 | M58: 2.2 | N58: 2 | O58: =SUM(V051_20[[#This Row],[MPAL]:[CALDERA]]) -> 4.2 | Q58: =(Q57-V051_20[[#This Row],[TOTAL ]])+V051_20[[#This Row],[FAENA]] -> 326.88833 | R58: 0 | S58: 0 | T58: 0 | U58: 0 | V58: 0 | W58: =SUM(V051_20[[#This Row],[MPAL2]:[GI]]) -> 0 | Y58: =(Y57-V051_20[[#This Row],[TOTAL]])+V051_20[[#This Row],[FAENA2]] -> 82.75 | AB58: =(AB57-V051_20[[#This Row],[CYLINDER MP]])+V051_20[[#This Row],[FAENA EN LTS]] -> 100 | AE58: =(AE57-V051_20[[#This Row],[CARTER MP.]])+V051_20[[#This Row],[FAENA EN LTS2]] -> 100 | AH58: =(AH57-V051_20[[#This Row],[MOT AUX]])+V051_20[[#This Row],[FAENA EN LTS]] -> 100 | AK58: =(AK57-V051_20[[#This Row],[HIDRAULICO]])+V051_20[[#This Row],[FAENA EN LTS3]] -> 100
A59: V051-19 | B59: 43836 | C59: 0.33333333 | D59: =IF(V051_20[[#This Row],[FECHA]]-B58=1,((V051_20[[#This Row],[HORA]]-C58)*24)+24,(V051_20[[#This Row],[HORA]]-C58)*24) -> 24 | E59: FONDEADO | F59: ETEN | I59: =IF(ISERROR(V051_20[[#This Row],[DISTANCIA POR CARTA]]/V051_20[[#This Row],[TIEMPO DE NAVEGACION]]),0,V051_20[[#This Row],[DISTANCIA POR CARTA]]/V051_20[[#This Row],[TIEMPO DE NAVEGACION]]) -> 0 | L59: 0 | M59: 2.2 | N59: 2 | O59: =SUM(V051_20[[#This Row],[MPAL]:[CALDERA]]) -> 4.2 | Q59: =(Q58-V051_20[[#This Row],[TOTAL ]])+V051_20[[#This Row],[FAENA]] -> 322.68833 | R59: 0 | S59: 0 | T59: 0 | U59: 0 | V59: 0 | W59: =SUM(V051_20[[#This Row],[MPAL2]:[GI]]) -> 0 | Y59: =(Y58-V051_20[[#This Row],[TOTAL]])+V051_20[[#This Row],[FAENA2]] -> 82.75 | AB59: =(AB58-V051_20[[#This Row],[CYLINDER MP]])+V051_20[[#This Row],[FAENA EN LTS]] -> 100 | AE59: =(AE58-V051_20[[#This Row],[CARTER MP.]])+V051_20[[#This Row],[FAENA EN LTS2]] -> 100 | AH59: =(AH58-V051_20[[#This Row],[MOT AUX]])+V051_20[[#This Row],[FAENA EN LTS]] -> 100 | AK59: =(AK58-V051_20[[#This Row],[HIDRAULICO]])+V051_20[[#This Row],[FAENA EN LTS3]] -> 100
A60: V051-19 | B60: 43836 | C60: 0.54166667 | D60: =IF(V051_20[[#This Row],[FECHA]]-B59=1,((V051_20[[#This Row],[HORA]]-C59)*24)+24,(V051_20[[#This Row],[HORA]]-C59)*24) -> 5 | E60: FONDEADO | F60: ANCLA ARRIBA ETEN | I60: =IF(ISERROR(V051_20[[#This Row],[DISTANCIA POR CARTA]]/V051_20[[#This Row],[TIEMPO DE NAVEGACION]]),0,V051_20[[#This Row],[DISTANCIA POR CARTA]]/V051_20[[#This Row],[TIEMPO DE NAVEGACION]]) -> 0 | L60: 0 | M60: 0.45833333 | N60: 0.41666667 | O60: =SUM(V051_20[[#This Row],[MPAL]:[CALDERA]]) -> 0.875 | Q60: =(Q59-V051_20[[#This Row],[TOTAL ]])+V051_20[[#This Row],[FAENA]] -> 321.81333 | R60: 0 | S60: 0 | T60: 0 | U60: 0 | V60: 0 | W60: =SUM(V051_20[[#This Row],[MPAL2]:[GI]]) -> 0 | Y60: =(Y59-V051_20[[#This Row],[TOTAL]])+V051_20[[#This Row],[FAENA2]] -> 82.75 | AB60: =(AB59-V051_20[[#This Row],[CYLINDER MP]])+V051_20[[#This Row],[FAENA EN LTS]] -> 100 | AE60: =(AE59-V051_20[[#This Row],[CARTER MP.]])+V051_20[[#This Row],[FAENA EN LTS2]] -> 100 | AH60: =(AH59-V051_20[[#This Row],[MOT AUX]])+V051_20[[#This Row],[FAENA EN LTS]] -> 100 | AK60: =(AK59-V051_20[[#This Row],[HIDRAULICO]])+V051_20[[#This Row],[FAENA EN LTS3]] -> 100
A61: V051-19 | B61: 43836 | C61: 0.59583333 | D61: =IF(V051_20[[#This Row],[FECHA]]-B60=1,((V051_20[[#This Row],[HORA]]-C60)*24)+24,(V051_20[[#This Row],[HORA]]-C60)*24) -> 1.3 | E61: MANIOBRA | F61: TCM ETEN | I61: =IF(ISERROR(V051_20[[#This Row],[DISTANCIA POR CARTA]]/V051_20[[#This Row],[TIEMPO DE NAVEGACION]]),0,V051_20[[#This Row],[DISTANCIA POR CARTA]]/V051_20[[#This Row],[TIEMPO DE NAVEGACION]]) -> 0 | L61: 0.10833333 | M61: 0.11916667 | N61: 0.10833333 | O61: =SUM(V051_20[[#This Row],[MPAL]:[CALDERA]]) -> 0.33583333 | Q61: =(Q60-V051_20[[#This Row],[TOTAL ]])+V051_20[[#This Row],[FAENA]] -> 321.4775 | R61: 0 | S61: 0 | T61: 0 | U61: 0 | V61: 0 | W61: =SUM(V051_20[[#This Row],[MPAL2]:[GI]]) -> 0 | Y61: =(Y60-V051_20[[#This Row],[TOTAL]])+V051_20[[#This Row],[FAENA2]] -> 82.75 | AB61: =(AB60-V051_20[[#This Row],[CYLINDER MP]])+V051_20[[#This Row],[FAENA EN LTS]] -> 100 | AE61: =(AE60-V051_20[[#This Row],[CARTER MP.]])+V051_20[[#This Row],[FAENA EN LTS2]] -> 100 | AH61: =(AH60-V051_20[[#This Row],[MOT AUX]])+V051_20[[#This Row],[FAENA EN LTS]] -> 100 | AK61: =(AK60-V051_20[[#This Row],[HIDRAULICO]])+V051_20[[#This Row],[FAENA EN LTS3]] -> 100
A62: V051-19 | B62: 43836 | C62: 0.72083333 | D62: =IF(V051_20[[#This Row],[FECHA]]-B61=1,((V051_20[[#This Row],[HORA]]-C61)*24)+24,(V051_20[[#This Row],[HORA]]-C61)*24) -> 3 | E62: OTRAS ACT. | F62: INICIO DESCARGA ETEN | I62: =IF(ISERROR(V051_20[[#This Row],[DISTANCIA POR CARTA]]/V051_20[[#This Row],[TIEMPO DE NAVEGACION]]),0,V051_20[[#This Row],[DISTANCIA POR CARTA]]/V051_20[[#This Row],[TIEMPO DE NAVEGACION]]) -> 0 | L62: 0 | M62: 0.3125 | N62: 0.25 | O62: =SUM(V051_20[[#This Row],[MPAL]:[CALDERA]]) -> 0.5625 | Q62: =(Q61-V051_20[[#This Row],[TOTAL ]])+V051_20[[#This Row],[FAENA]] -> 320.915 | R62: 0 | S62: 0 | T62: 0 | U62: 0 | V62: 0 | W62: =SUM(V051_20[[#This Row],[MPAL2]:[GI]]) -> 0 | Y62: =(Y61-V051_20[[#This Row],[TOTAL]])+V051_20[[#This Row],[FAENA2]] -> 82.75 | AB62: =(AB61-V051_20[[#This Row],[CYLINDER MP]])+V051_20[[#This Row],[FAENA EN LTS]] -> 100 | AE62: =(AE61-V051_20[[#This Row],[CARTER MP.]])+V051_20[[#This Row],[FAENA EN LTS2]] -> 100 | AH62: =(AH61-V051_20[[#This Row],[MOT AUX]])+V051_20[[#This Row],[FAENA EN LTS]] -> 100 | AK62: =(AK61-V051_20[[#This Row],[HIDRAULICO]])+V051_20[[#This Row],[FAENA EN LTS3]] -> 100
